#VRML_SIM R2021b utf8
WorldInfo {
  coordinateSystem "NUE"
}
Viewpoint {
  orientation -0.4752223492235546 -0.6990527231980543 -0.5343117151886435 2.040440682805006
  position -0.6295569901453358 2.7076778956957703 -0.03634673524724513
}
TexturedBackground {
  texture "factory"
}
TexturedBackgroundLight {
}
DEF RedCylinder Solid {
  translation 0.508 0.1492512113100835 0.508
  rotation 0.08557078139121713 -0.9940203475970536 -0.06783207158217534 7.825316214650804e-16
  children [
    Shape {
      appearance PBRAppearance {
        baseColor 1 0 0
        roughness 1
        metalness 0
      }
      geometry Cylinder {
        height 0.381
        radius 0.08
      }
    }
  ]
  name "solid(1)"
  boundingObject DEF landmark Shape {
    appearance PBRAppearance {
      baseColor 0 1 1
      roughness 1
      metalness 0
    }
    geometry Cylinder {
      height 0.3
      radius 0.045
    }
  }
  physics DEF landmarkPH Physics {
  }
  locked TRUE
  recognitionColors [
    1 0 0
  ]
}
DEF YellowCylinder Solid {
  translation 0.508 0.1492512113100835 -0.508
  rotation 0.07865102290131015 -0.9951208968569675 -0.059568592690800844 6.385343747797566e-16
  children [
    Shape {
      appearance PBRAppearance {
        baseColor 1 1 0
        roughness 1
        metalness 0
      }
      geometry Cylinder {
        height 0.381
        radius 0.08
      }
    }
  ]
  name "solid(4)"
  boundingObject DEF landmark Shape {
    appearance PBRAppearance {
      baseColor 0 1 1
      roughness 1
      metalness 0
    }
    geometry Cylinder {
      height 0.3
      radius 0.045
    }
  }
  physics DEF landmarkPH Physics {
  }
  locked TRUE
  recognitionColors [
    1 1 0
  ]
}
DEF GreenCylinder Solid {
  translation -0.508 0.1492512113100835 -0.508
  rotation 0.015728114948195395 -0.9965940555194454 -0.08095007661195337 7.095769002690444e-16
  children [
    Shape {
      appearance PBRAppearance {
        baseColor 0 1 0
        roughness 1
        metalness 0
      }
      geometry Cylinder {
        height 0.381
        radius 0.08
      }
    }
  ]
  name "solid(3)"
  boundingObject DEF landmark Shape {
    appearance PBRAppearance {
      baseColor 0 1 1
      roughness 1
      metalness 0
    }
    geometry Cylinder {
      height 0.3
      radius 0.045
    }
  }
  physics DEF landmarkPH Physics {
  }
  locked TRUE
  recognitionColors [
    0 1 0
  ]
}
DEF BlueCylinder Solid {
  translation -0.508 0.1492512113100835 0.508
  rotation 0.11300385483637347 -0.9892035937490196 -0.09330797879144305 9.382238964120569e-16
  children [
    Shape {
      appearance PBRAppearance {
        baseColor 0 0 1
        roughness 1
        metalness 0
      }
      geometry Cylinder {
        height 0.381
        radius 0.08
      }
    }
  ]
  name "solid(5)"
  boundingObject DEF landmark Shape {
    appearance PBRAppearance {
      baseColor 0 1 1
      roughness 1
      metalness 0
    }
    geometry Cylinder {
      height 0.3
      radius 0.045
    }
  }
  physics DEF landmarkPH Physics {
  }
  locked TRUE
  recognitionColors [
    0 0 1
  ]
}
DEF area RectangleArena {
  floorSize 1.016 1.016
  floorTileSize 0.508 0.508
  wallAppearance BrushedAluminium {
    colorOverride 0 0 0
  }
}
DEF epuck E-puck {
  hidden position_0_0 7.6613629040881e-09
  hidden position_0_1 -2.5608527952908554e-08
  hidden rotation_2 0.9999999999999999 0 0 2.9802322387695313e-08
  translation 0.36557161265932747 -0.00010128589968788453 0.39206611038287487
  rotation -0.04242502427919352 -0.9990992125252639 0.0009385341268470215 0.0037931049679636357
  controller "lab3task2"
  supervisor TRUE
  camera_width 50
  turretSlot [
    InertialUnit {
    }
    DEF righthinge HingeJoint {
      jointParameters HingeJointParameters {
        position -5.694721760818311e-08
        axis -1 0 0
        anchor 0 0.025 0
      }
      device [
        RotationalMotor {
          name "right wheel motor"
          consumptionFactor 70
          controlPID 8 2 0.5
        }
        PositionSensor {
          name "right wheel sensor"
        }
      ]
      endPoint Solid {
        translation 0.04500995778380095 0.025013380760288632 -2.467192909007314e-05
        rotation 0.9999993203499445 0.00100527347036125 -0.0005905293378185355 4.636837179001848
        children [
          DEF WHEEL Transform {
            translation -0.007 0.01 -0.05
            rotation 0 0 1 1.57
            children [
              Shape {
                appearance PBRAppearance {
                  baseColor 0 0 0
                  transparency 1
                  roughness 1
                  metalness 0
                }
                geometry Cylinder {
                  height 0.01
                  radius 0.02
                }
              }
            ]
            rotationStep 0.25
          }
        ]
        name "right wheel(1)"
        boundingObject USE WHEEL
        physics DEF PHYSICS_WHEEL Physics {
          density -1
          mass 0.05
        }
        rotationStep 0.25
      }
    }
    DEF lefthinge HingeJoint {
      jointParameters HingeJointParameters {
        position 3.1019290357715375e-08
        axis -1 0 0
        anchor 0 0.025 0
      }
      device [
        RotationalMotor {
          name "left wheel motor"
          consumptionFactor 70
          controlPID 8 0 0
        }
        PositionSensor {
          name "left wheel sensor"
        }
      ]
      endPoint Solid {
        translation -0.04501012942703836 0.02497767197586043 -4.5733975469435584e-05
        rotation -0.9999982113395944 0.000472752647491291 -0.0018313444641409118 1.2425810513081945
        children [
          DEF WHEEL Transform {
            translation 0.007 0 -0.05
            rotation 0 0 1 1.57
            children [
              Shape {
                appearance PBRAppearance {
                  baseColor 0.1 0.1 0.1
                  transparency 1
                  roughness 1
                  metalness 0
                }
                geometry Cylinder {
                  height 0.01
                  radius 0.02
                }
              }
            ]
            rotationStep 0.25
          }
        ]
        name "left wheel(1)"
        boundingObject USE WHEEL
        physics DEF PHYSICS_WHEEL Physics {
          density -1
          mass 0.05
        }
      }
    }
    DEF front_ds DistanceSensor {
      translation 0 0 -0.045
      rotation 0 1 0 1.5708
      name "front_ds"
      recognitionColors [
        0 0 0
      ]
      lookupTable [
        0 0 0
        1.27 1.27 0
      ]
    }
    DEF right_ds DistanceSensor {
      translation 0.035 -0.01 -0.01
      name "right_ds"
      lookupTable [
        0 0 0
        1.27 1.27 0
      ]
    }
    DEF left_ds DistanceSensor {
      translation -0.035 -0.01 -0.01
      rotation 0 1 0 3.14159
      name "left_ds"
      lookupTable [
        0 0 0
        1.27 1.27 0
      ]
    }
    Camera {
      translation 0 -0.01 -0.045
      name "camera1"
      recognitionColors [
        1 1 0
      ]
      fieldOfView 1.57
      width 80
      height 80
      recognition Recognition {
      }
    }
  ]
}
