#VRML_SIM R2021b utf8
WorldInfo {
  coordinateSystem "NUE"
}
Viewpoint {
  orientation -0.9995684664308597 -0.028343365448906567 -0.007715863664474055 0.9772905723406264
  position -0.3258314298010362 1.8495843408759227 1.0750912131012895
}
TexturedBackground {
  texture "factory"
}
TexturedBackgroundLight {
}
WoodenBox {
  translation -0.2541 -4.44089e-16 0.0584928
  name "wooden box(1)"
  size 0.508 0.2 0.01
  locked TRUE
}
WoodenBox {
  translation -0.513625 2.22045e-16 -0.444876
  name "wooden box(3)"
  size 0.508 0.2 0.01
  locked TRUE
}
WoodenBox {
  translation -0.259053 -1.24345e-14 -0.325153
  rotation 0 1 0 -1.5707953071795862
  name "wooden box(2)"
  size 0.251 0.2 0.01
  locked TRUE
}
WoodenBox {
  translation -0.507275 -1.13243e-14 -0.0600948
  rotation 0 1 0 -1.5707953071795862
  name "wooden box(4)"
  size 0.251 0.2 0.01
  locked TRUE
}
WoodenBox {
  translation -0.00641655 -1.11023e-14 -0.194548
  rotation 0 1 0 -1.5707953071795862
  name "wooden box(5)"
  size 0.508 0.2 0.01
  locked TRUE
}
DEF area RectangleArena {
  translation -0.257628 -4.44089e-16 -0.192172
  floorSize 1.016 1.016
  floorTileSize 0.508 0.508
  wallAppearance BrushedAluminium {
    colorOverride 0 0 0
  }
}
DEF epuck E-puck {
  hidden position_0_0 7.661356786635406e-09
  hidden position_0_1 -2.5608522718152286e-08
  hidden rotation_2 1 0 0 2.9802322387695313e-08
  translation 0.1285506126593277 -0.00010128589870999315 0.1866491103828788
  rotation -0.04242505476892337 -0.9990992112306174 0.0009385340760332658 0.0037931049728747324
  controller "lab3task3"
  supervisor TRUE
  camera_width 50
  turretSlot [
    InertialUnit {
    }
    DEF righthinge HingeJoint {
      jointParameters HingeJointParameters {
        position -7.818440383999814e-08
        axis -1 0 0
        anchor 0 0.025 0
      }
      device [
        RotationalMotor {
          name "right wheel motor"
          consumptionFactor 70
          controlPID 8 2 0.5
        }
        PositionSensor {
          name "right wheel sensor"
        }
      ]
      endPoint Solid {
        translation 0.04500995778380096 0.025013380760812595 -2.467192880590344e-05
        rotation 0.9999993203499311 0.0010052734865289399 -0.0005905293329578136 4.636837200239019
        children [
          DEF WHEEL Transform {
            translation -0.007 0.01 -0.05
            rotation 0 0 1 1.57
            children [
              Shape {
                appearance PBRAppearance {
                  baseColor 0 0 0
                  transparency 1
                  roughness 1
                  metalness 0
                }
                geometry Cylinder {
                  height 0.01
                  radius 0.02
                }
              }
            ]
            rotationStep 0.25
          }
        ]
        name "right wheel(1)"
        boundingObject USE WHEEL
        physics DEF PHYSICS_WHEEL Physics {
          density -1
          mass 0.05
        }
        rotationStep 0.25
      }
    }
    DEF lefthinge HingeJoint {
      jointParameters HingeJointParameters {
        position 3.101928452301603e-08
        axis -1 0 0
        anchor 0 0.025 0
      }
      device [
        RotationalMotor {
          name "left wheel motor"
          consumptionFactor 70
          controlPID 8 0 0
        }
        PositionSensor {
          name "left wheel sensor"
        }
      ]
      endPoint Solid {
        translation -0.04501012942703836 0.02497767197586043 -4.573397546943571e-05
        rotation -0.9999982113395943 0.0004727526474912983 -0.001831344464140918 1.2425810513081883
        children [
          DEF WHEEL Transform {
            translation 0.007 0 -0.05
            rotation 0 0 1 1.57
            children [
              Shape {
                appearance PBRAppearance {
                  baseColor 0.1 0.1 0.1
                  transparency 1
                  roughness 1
                  metalness 0
                }
                geometry Cylinder {
                  height 0.01
                  radius 0.02
                }
              }
            ]
            rotationStep 0.25
          }
        ]
        name "left wheel(1)"
        boundingObject USE WHEEL
        physics DEF PHYSICS_WHEEL Physics {
          density -1
          mass 0.05
        }
      }
    }
    DEF front_ds DistanceSensor {
      translation 0 0 -0.045
      rotation 0 1 0 1.5708
      name "front_ds"
      recognitionColors [
        0 0 0
      ]
      lookupTable [
        0 0 0
        1.27 1.27 0
      ]
    }
    DEF right_ds DistanceSensor {
      translation 0.035 -0.01 -0.01
      name "right_ds"
      lookupTable [
        0 0 0
        1.27 1.27 0
      ]
    }
    DEF left_ds DistanceSensor {
      translation -0.035 -0.01 -0.01
      rotation 0 1 0 3.14159
      name "left_ds"
      lookupTable [
        0 0 0
        1.27 1.27 0
      ]
    }
    Camera {
      translation 0 -0.01 -0.045
      name "camera1"
      recognitionColors [
        1 1 0
      ]
      fieldOfView 1.57
      width 80
      height 80
      recognition Recognition {
      }
    }
  ]
}
